Workbook

Sheet START
A1: DZIF Intelligence Master | v2.3
A3: Pflegequelle Excel | Geprueft am 29.10.2026 | Routine: Competitor, Funding, BD
A5: ZWECK: Quellen und Entitaeten finden, projektbezogen auswaehlen und Recherche priorisieren.
A6: KEINE Ergebnisdatenbank: Phasen, Calls, Fristen, Deals und klinische Evidenz werden live verifiziert.
A7: Reservierte Firmen bleiben in Excel. JSON enthaelt nur operative Routen und deren Abhaengigkeiten.
B9: Organisationen | C9: M01 gesamt | D9: M01 operativ | E9: Funding-Routen | F9: Quellen
B10: =COUNTA(ENTITY_MASTER!A2:A266) -> 265 | C10: =COUNTA(M01_COMPETITORS!A2:A245) -> 244 | D10: =COUNTIF(M01_COMPETITORS!Q2:Q245,"CONDITIONAL")+COUNTIF(M01_COMPETITORS!Q2:Q245,"CORE") -> 103 | E10: =COUNTA(M05_FUNDING!A2:A68) -> 67 | F10: =COUNTA(SOURCE_REGISTRY!A2:A246) -> 245
A12: Flagship-Pruefung | C12: 11 reale DZIF-Beispiele; Scope, Korrektur und verbleibende Luecken.
A13: Effizienzentscheidungen | C13: Was bleibt, was archiviert ist und welche Unsicherheiten bestehen.
A14: Offene Datenpruefung | C14: Keine Pflicht zur erneuten Vollrecherche aller Reservefirmen.
A16: Modul | D16: Katalogzeilen | E16: Routine | F16: Funktion
A17: M01 | Competitor & Asset Intelligence | D17: =COUNTA(M01_COMPETITORS!A2:A245) -> 244 | E17: AKTIV | F17: Suchprofile
A18: M02 | Clinical Trial Intelligence | D18: =COUNTA(M02_CLINICAL!A2:A6) -> 5 | E18: RESERVIERT | F18: Quellenanker
A19: M03 | Scientific & Technology Intelligence | D19: =COUNTA(M03_SCI_TECH!A2:A4) -> 3 | E19: RESERVIERT | F19: Quellenanker
A20: M04 | Regulatory Intelligence | D20: =COUNTA(M04_REGULATORY!A2:A11) -> 10 | E20: RESERVIERT | F20: Quellenanker
A21: M05 | Funding Opportunities | D21: =COUNTA(M05_FUNDING!A2:A68) -> 67 | E21: AKTIV | F21: Suchprofile
A22: M06 | BD & Partnering Intelligence | D22: =COUNTA(M06_BD_PARTNERS!A2:A79) -> 78 | E22: AKTIV | F22: Suchprofile
A23: M07 | Deal & Investment Intelligence | D23: =COUNTA(M07_DEALS!A2:A58) -> 57 | E23: RESERVIERT | F23: Suchprofile
A24: M08 | Conference & Event Intelligence | D24: =COUNTA(M08_EVENTS!A2:A8) -> 7 | E24: RESERVIERT | F24: Quellenanker
A25: M09 | Clinical & Medical Landscape | D25: =COUNTA(M09_MEDICAL!A2:A7) -> 6 | E25: RESERVIERT | F25: Quellenanker
A26: M10 | IP & Patent Intelligence | D26: =COUNTA(M10_IP_PATENT!A2:A4) -> 3 | E26: RESERVIERT | F26: Quellenanker
A27: M11 | CMC & Manufacturing Intelligence | D27: =COUNTA(M11_CMC!A2:A8) -> 7 | E27: RESERVIERT | F27: Quellenanker
A28: M12 | Policy, Market & Access Intelligence | D28: =COUNTA(M12_POLICY_ACCESS!A2:A8) -> 7 | E28: RESERVIERT | F28: Quellenanker
A31: PFLEGE | B31: IDs erhalten; nur belegte neue Angaben eintragen. Pflichtfelder nicht leer lassen. Optionale Elternbeziehung, Alias oder API-Felder duerfen leer sein.
A32: AUSWAHL | B32: own_asset_ids im Projekt-Intake angeben. Gleicher Erreger ist nicht automatisch gleicher klinischer Zweck. Rueckstellungen sind sichtbar.
A33: EXPORT | B33: Mit export_master.py neu erzeugen. DISCOVERY/PAUSED/INACTIVE und unreferenzierte Entitaeten/Quellen werden nicht in den Standardexport geladen.
A34: ARCHIV | B34: Historische Seeds, Discovery Pool und 18 ausgelagerte Blaetter liegen unveraendert im Integrations-/Auditpaket; v2.2-Original ebenfalls enthalten.
A35: ABNAHME | B35: 109 lokale technische Checks bestanden. 11 Flagships plus 13 Kontrastprofile. Keine externe Recall-Messung und kein Langdock-End-to-End-Test.
A36: RECHTE | B36: GlobalData-abgeleitete Inhalte nur im geklaerten Nutzungsrahmen. Privates GitHub-Repository allein ersetzt keine Weitergaberechte.

Sheet MODULE_CONFIG
A1: module_id | B1: module_name | C1: sheet_name | D1: module_priority | E1: routine_enabled | F1: run_cadence | G1: candidate_cap | H1: max_live_checks | I1: discovery_queries | J1: freshness_days | K1: catalog_review_months | L1: selection_basis | M1: output_focus | N1: policy_note | O1: catalog_status | P1: integration_status | Q1: default_query_id
A2: M01 | B2: Competitor & Asset Intelligence | C2: M01_COMPETITORS | D2: SEHR_HOCH | E2: YES | F2: MONTHLY | G2: 25 | H2: 12 | I2: 2 | J2: 30 | K2: 12 | L2: EVIDENCE_TIER > pathogen/indication/target > MoA/modality > stage > specific topic > base priority | M2: Asset / Wettbewerbsentwicklung | N2: Direct asset and clinical-context anchors precede general companies; no forced field quotas; all budget omissions visible. | O2: POPULATED_REFERENCE_INDEX | P2: LOCAL_SELECTOR_ONLY | Q2: M01_ENTITY
A3: M02 | B3: Clinical Trial Intelligence | C3: M02_CLINICAL | D3: SEHR_HOCH | E3: NO | F3: MONTHLY | G3: 15 | H3: 8 | I3: 2 | J3: 14 | K3: 12 | L3: SCOPE_MATCH;PROJECT_MATCH;PRIORITY;STABLE_ID | M3: Studie / Studiendelta | N3: Budget = Planungsannahme. Erst lokal filtern; Quellen nicht vollstaendig in Agentenprompt laden. Unabhaengige Discovery bleibt. Kein Persistenz-/Live-Connector-Test. | O3: POPULATED_REFERENCE_INDEX | P3: LOCAL_SELECTOR_ONLY | Q3: M02_REGISTRY
A4: M03 | B4: Scientific & Technology Intelligence | C4: M03_SCI_TECH | D4: SEHR_HOCH | E4: NO | F4: QUARTERLY | G4: 12 | H4: 6 | I4: 3 | J4: 60 | K4: 12 | L4: SCOPE_MATCH;PROJECT_MATCH;PRIORITY;STABLE_ID | M4: Publikation / Technologieentwicklung | N4: Budget = Planungsannahme. Erst lokal filtern; Quellen nicht vollstaendig in Agentenprompt laden. Unabhaengige Discovery bleibt. Kein Persistenz-/Live-Connector-Test. | O4: POPULATED_REFERENCE_INDEX | P4: LOCAL_SELECTOR_ONLY | Q4: M03_LITERATURE
A5: M04 | B5: Regulatory Intelligence | C5: M04_REGULATORY | D5: SEHR_HOCH | E5: NO | F5: QUARTERLY | G5: 10 | H5: 5 | I5: 2 | J5: 60 | K5: 12 | L5: SCOPE_MATCH;PROJECT_MATCH;PRIORITY;STABLE_ID | M5: Regulatorisches Dokument / Änderung | N5: Budget = Planungsannahme. Erst lokal filtern; Quellen nicht vollstaendig in Agentenprompt laden. Unabhaengige Discovery bleibt. Kein Persistenz-/Live-Connector-Test. | O5: POPULATED_REFERENCE_INDEX | P5: LOCAL_SELECTOR_ONLY | Q5: M04_GUIDANCE
A6: M05 | B6: Funding Opportunities | C6: M05_FUNDING | D6: SEHR_HOCH | E6: YES | F6: WEEKLY | G6: 18 | H6: 12 | I6: 2 | J6: 7 | K6: 12 | L6: SCOPE_MATCH;PROJECT_MATCH;PRIORITY;STABLE_ID | M6: Call / Förderchance | N6: Budget = Planungsannahme. Erst lokal filtern; Quellen nicht vollstaendig in Agentenprompt laden. Unabhaengige Discovery bleibt. Kein Persistenz-/Live-Connector-Test. | O6: POPULATED_REFERENCE_INDEX | P6: LOCAL_SELECTOR_ONLY | Q6: M05_SOURCE
A7: M06 | B7: BD & Partnering Intelligence | C7: M06_BD_PARTNERS | D7: SEHR_HOCH | E7: YES | F7: QUARTERLY | G7: 15 | H7: 8 | I7: 2 | J7: 45 | K7: 12 | L7: SCOPE_MATCH;PROJECT_MATCH;PRIORITY;STABLE_ID | M7: Partnerkandidat / Strategisches Signal | N7: Equity only with explicit company/spinout financing strategy; licensing, co-development and nonprofit R&D assessed separately. | O7: POPULATED_REFERENCE_INDEX | P7: LOCAL_SELECTOR_ONLY | Q7: M06_ENTITY
A8: M07 | B8: Deal & Investment Intelligence | C8: M07_DEALS | D8: HOCH | E8: NO | F8: MONTHLY | G8: 10 | H8: 5 | I8: 2 | J8: 30 | K8: 12 | L8: SCOPE_MATCH;PROJECT_MATCH;PRIORITY;STABLE_ID | M8: Transaktion / Finanzierung | N8: Optional watches only. Activation requires validated deal-event results schema and explicit approval; master contains NO transactions. | O8: POPULATED_REFERENCE_INDEX | P8: RESERVED_DEAL_EVENT_STORE_NOT_VALIDATED | Q8: M07_ENTITY
A9: M08 | B9: Conference & Event Intelligence | C9: M08_EVENTS | D9: HOCH | E9: NO | F9: MONTHLY | G9: 10 | H9: 5 | I9: 2 | J9: 30 | K9: 12 | L9: SCOPE_MATCH;PROJECT_MATCH;PRIORITY;STABLE_ID | M9: Event-Ausgabe / Deadline | N9: Budget = Planungsannahme. Erst lokal filtern; Quellen nicht vollstaendig in Agentenprompt laden. Unabhaengige Discovery bleibt. Kein Persistenz-/Live-Connector-Test. | O9: POPULATED_REFERENCE_INDEX | P9: LOCAL_SELECTOR_ONLY | Q9: M08_EVENT
A10: M09 | B10: Clinical & Medical Landscape | C10: M09_MEDICAL | D10: HOCH | E10: NO | F10: QUARTERLY | G10: 10 | H10: 5 | I10: 2 | J10: 90 | K10: 12 | L10: SCOPE_MATCH;PROJECT_MATCH;PRIORITY;STABLE_ID | M10: Leitlinien-/SoC-Update | N10: Budget = Planungsannahme. Erst lokal filtern; Quellen nicht vollstaendig in Agentenprompt laden. Unabhaengige Discovery bleibt. Kein Persistenz-/Live-Connector-Test. | O10: POPULATED_REFERENCE_INDEX | P10: LOCAL_SELECTOR_ONLY | Q10: M09_MEDICAL
A11: M10 | B11: IP & Patent Intelligence | C11: M10_IP_PATENT | D11: MITTEL_HOCH | E11: NO | F11: QUARTERLY | G11: 10 | H11: 4 | I11: 2 | J11: 90 | K11: 12 | L11: SCOPE_MATCH;PROJECT_MATCH;PRIORITY;STABLE_ID | M11: Patentfamilie / neue Anmeldung | N11: Budget = Planungsannahme. Erst lokal filtern; Quellen nicht vollstaendig in Agentenprompt laden. Unabhaengige Discovery bleibt. Kein Persistenz-/Live-Connector-Test. | O11: POPULATED_REFERENCE_INDEX | P11: LOCAL_SELECTOR_ONLY | Q11: M10_PATENT
A12: M11 | B12: CMC & Manufacturing Intelligence | C12: M11_CMC | D12: MITTEL | E12: NO | F12: QUARTERLY | G12: 10 | H12: 4 | I12: 2 | J12: 120 | K12: 12 | L12: SCOPE_MATCH;PROJECT_MATCH;PRIORITY;STABLE_ID | M12: CMC-Standard / Technologie / Lieferant | N12: Budget = Planungsannahme. Erst lokal filtern; Quellen nicht vollstaendig in Agentenprompt laden. Unabhaengige Discovery bleibt. Kein Persistenz-/Live-Connector-Test. | O12: POPULATED_REFERENCE_INDEX | P12: LOCAL_SELECTOR_ONLY | Q12: M11_CMC
A13: M12 | B13: Policy, Market & Access Intelligence | C13: M12_POLICY_ACCESS | D13: MITTEL | E13: NO | F13: QUARTERLY | G13: 10 | H13: 4 | I13: 2 | J13: 90 | K13: 12 | L13: SCOPE_MATCH;PROJECT_MATCH;PRIORITY;STABLE_ID | M13: Policy-/Access-Entwicklung | N13: Budget = Planungsannahme. Erst lokal filtern; Quellen nicht vollstaendig in Agentenprompt laden. Unabhaengige Discovery bleibt. Kein Persistenz-/Live-Connector-Test. | O13: POPULATED_REFERENCE_INDEX | P13: LOCAL_SELECTOR_ONLY | Q13: M12_POLICY

Sheet FLAGSHIP_CHECK
A1: project_id | B1: project_name | C1: scope | D1: change | E1: official_url | F1: scenario_assumption | G1: m01_profiles_before | H1: m01_profiles_after | I1: m01_planned_live_requests | J1: important_anchors | K1: remaining_gap | L1: acceptance
A2: DZIF-FLAG-HEV | B2: HEVbnAb | C2: HEV / neutralisierender Antikoerper / akute und chronische Infektion | D2: Spezifische HEV-Indikationen ergaenzt; Hecolin als Praeventionsprodukt herabgestuft. | E2: https://www.dzif.de/de/hevbnab-breit-neutralisierende-antikoerper-gegen-das-hepatitis-e-virus | F2: Academic applicant, no equity strategy; scenario phase only for routing test, not independently verified current study status. | G2: 10 | H2: 5 | I2: 7 | J2: DIRECT_COMPETITOR_DISCOVERY_OPEN | K2: Kein direkt konkurrierendes therapeutisches HEV-mAb-Programm in dieser gezielten Recherche belegt; offene akademische/klinische Suche bleibt notwendig. | L2: LOCAL_ROUTING_OBSERVED; NOT_EXTERNAL_RECALL; LANGDOCK_NOT_RUN
A3: DZIF-FLAG-EVREA | B3: EVREA-Phage | C3: E. faecium / lebende Phagen / intestinale VRE-Dekolonisierung | D3: E_FAECIUM und Dekolonisierung ergaenzt; SNIPR001 bleibt E.-coli-Kontextalternative. | E3: https://www.dzif.de/de/evrea-phage-mit-phagen-gegen-das-darmbakterium-enterococcus-faecium | F3: Academic applicant, no equity strategy; scenario phase only for routing test, not independently verified current study status. | G3: 0 | H3: 6 | I3: 8 | J3: SNIPR Biome ApS: PLANNED | K3: Kein direkter E.-faecium-Phagenkonkurrent belegt. Andere Spezies, systemische Therapie und Dekolonisierung nicht gleichsetzen. | L3: LOCAL_ROUTING_OBSERVED; NOT_EXTERNAL_RECALL; LANGDOCK_NOT_RUN
A4: DZIF-FLAG-PANTIPA | B4: PANTIPA / UHC-D9b | C4: P. aeruginosa / anti-PcrV / HAP-VAP-Therapieszenario | D4: Spezifische Anker geschuetzt; hoechstens fuenf allgemeine Firmenprofile; akademische Discovery erhalten. | E4: https://www.dzif.de/de/pantipa-monoklonale-antikoerper-gegen-pseudomonas-aeruginosa | F4: User-supplied HAP/VAP treatment scenario; public DZIF page also discusses prophylaxis. PRECLINICAL/CMC test input, not a verified current phase. | G4: 25 | H4: 9 | I4: 11 | J4: Infex Therapeutics: PLANNED; AstraZeneca: PLANNED; Armata Pharmaceuticals: PLANNED | K4: NCFB/CF ist nicht akute HAP/VAP. Aktuelle Phase, Aktivitaet, Differenzierung und Versorgungskontext live pruefen. | L4: LOCAL_ROUTING_OBSERVED; NOT_EXTERNAL_RECALL; LANGDOCK_NOT_RUN
A5: DZIF-FLAG-H052 | B5: H052 / alpha-toxin small molecules | C5: S. aureus / alpha-Toxin-Inhibition / Small Molecule / Pneumonie | D5: AR-301 als Target-/Indikationsalternative ergaenzt; IBT-Niedersachsen als Forschungsroute. | E5: https://www.dzif.de/de/niedermolekulare-inhibitoren-des-alpha-toxins-von-staphylococcus-aureus-gegen-schwere | F5: Academic applicant, no equity strategy; scenario phase only for routing test, not independently verified current study status. | G5: 25 | H5: 6 | I5: 5 | J5: Aridis Pharmaceuticals Inc: PLANNED | K5: Aktuelle Fortfuehrung/Rechte und Studienergebnisse von AR-301 unabhaengig pruefen; anderer Wirkstofftyp. | L5: LOCAL_ROUTING_OBSERVED; NOT_EXTERNAL_RECALL; LANGDOCK_NOT_RUN
A6: DZIF-FLAG-BTZ043 | B6: BTZ-043 | C6: M. tuberculosis / DprE1 / Small Molecule / Kombinationstherapie | D6: Otsuka mit offizieller Pipeline und Quabodepistat-Anker nachqualifiziert. | E6: https://www.dzif.de/de/neuer-wirkstoff-btz-043-gegen-tuberkulose | F6: Academic applicant, no equity strategy; scenario phase only for routing test, not independently verified current study status. | G6: 20 | H6: 7 | I6: 9 | J6: Otsuka Pharmaceutical Co Ltd: PLANNED; TB Alliance: PLANNED | K6: Kombinationsregime und aktuelle Studienaktivitaet nicht im Master gepflegt. Weitere DprE1-/Regimenprogramme live recherchieren. | L6: LOCAL_ROUTING_OBSERVED; NOT_EXTERNAL_RECALL; LANGDOCK_NOT_RUN
A7: DZIF-FLAG-HY133 | B7: HY-133 | C7: S. aureus / Endolysin-Protein / nasale Dekolonisierung | D7: ENDOLYSIN getrennt von PHAGE; HYpharm/HY-133 im eigenen Projekt nicht als Konkurrenz. | E7: https://www.dzif.de/de/neuer-wirkstoff-gegen-krankenhauskeim | F7: Academic applicant, no equity strategy; scenario phase only for routing test, not independently verified current study status. | G7: 25 | H7: 5 | I7: 5 | J7: DIRECT_COMPETITOR_DISCOVERY_OPEN | K7: Direkte nasale Dekolonisierungsalternativen und Standard of Care fehlen als vollstaendig qualifizierte Asset-Liste; gezielte offene Suche. | L7: LOCAL_ROUTING_OBSERVED; NOT_EXTERNAL_RECALL; LANGDOCK_NOT_RUN
A8: DZIF-FLAG-CORA | B8: Corallopyronin A | C8: Filarienindikation / Wolbachia-Symbiont / Corallopyronin A | D8: Filarien und Wolbachia getrennt; DNDi/Emodepsid als klinisch anderer Ansatz. | E8: https://www.dzif.de/de/corallopyronin-neues-antibiotikum-gegen-wurminfektionen | F8: Academic applicant, no equity strategy; scenario phase only for routing test, not independently verified current study status. | G8: 0 | H8: 6 | I8: 5 | J8: Drugs for Neglected Diseases initiative: PLANNED | K8: DNDi hat zugleich Partner- und alternative Asset-Rollen. Weitere antifilariale Programme und Phase live verifizieren. | L8: LOCAL_ROUTING_OBSERVED; NOT_EXTERNAL_RECALL; LANGDOCK_NOT_RUN
A9: DZIF-FLAG-MERS | B9: MVA-MERS-S | C9: MERS-CoV / MVA-Vektorimpfstoff / Praevention | D9: Oxford/ChAdOx1-MERS aus vorhandener Reserve mit stabiler ID uebernommen. | E9: https://www.dzif.de/de/entwicklung-eines-mers-impfstoffes | F9: Academic applicant, no equity strategy; scenario phase only for routing test, not independently verified current study status. | G9: 10 | H9: 6 | I9: 8 | J9: University of Oxford: PLANNED | K9: Oxford-Ankuendigung belegt historischen Programmscope, nicht aktuelle Aktivitaet oder heutige Lizenzrechte. | L9: LOCAL_ROUTING_OBSERVED; NOT_EXTERNAL_RECALL; LANGDOCK_NOT_RUN
A10: DZIF-FLAG-EBV | B10: EBV vaccine / VLP | C10: EBV / VLP-Impfstoff / Praevention der Mononukleose | D10: Moderna/mRNA-1189-Praeventionsanker; EBV-PTLD-Zelltherapie nicht als direkte Impfkonkurrenz. | E10: https://www.dzif.de/de/ein-impfstoff-gegen-das-epstein-barr-virus | F10: Academic applicant, no equity strategy; scenario phase only for routing test, not independently verified current study status. | G10: 11 | H10: 6 | I10: 8 | J10: Moderna: PLANNED | K10: EBViously-Projektrolle und aktuelle Kandidaten/Studien live klaeren; Impfziel von PTLD-Therapie trennen. | L10: LOCAL_ROUTING_OBSERVED; NOT_EXTERNAL_RECALL; LANGDOCK_NOT_RUN
A11: DZIF-FLAG-THERVACB | B11: TherVacB | C11: HBV / therapeutische Impfung / chronische Infektion | D11: THERAPEUTIC_VACCINE separat; BRII-179-Anker statt generischer Praeventionsprofile. | E11: https://www.dzif.de/de/thervacb-eine-therapeutische-impfung-gegen-hepatitis-b | F11: Academic applicant, no equity strategy; scenario phase only for routing test, not independently verified current study status. | G11: 10 | H11: 8 | I11: 10 | J11: Brii Biosciences Ltd: PLANNED | K11: Aktuelle Kombinationen, Rekrutierung und Impfregime gehoeren in die Ergebnisdatenbank; Uebersichtsseite enthaelt alte Zeitangaben. | L11: LOCAL_ROUTING_OBSERVED; NOT_EXTERNAL_RECALL; LANGDOCK_NOT_RUN
A12: DZIF-FLAG-HEPCLUDEX | B12: Hepcludex / bulevirtide | C12: HDV / Bulevirtid-Peptid / zugelassenes Translationsbeispiel | D12: Eigenes Bulevirtid ausgeschlossen, Vir/Assembly als Alternativen erhalten; kein Fruehphasen-Funding-Test. | E12: https://www.dzif.de/de/hepcludex-erstes-medikament-fuer-hepatitis-d-zugelassen | F12: Approved reference; industry/non-equity scenario for M01/M06 only. No fresh clinical-stage inference from overview. | G12: 10 | H12: 7 | I12: 9 | J12: Vir Biotechnology Inc: PLANNED; Assembly Biosciences: PLANNED | K12: Zugelassener Referenzfall, kein neues fruehes Entwicklungsprojekt. Aktuelle HDV-Alternativen und Access-Fragen bleiben live. | L12: LOCAL_ROUTING_OBSERVED; NOT_EXTERNAL_RECALL; LANGDOCK_NOT_RUN

Sheet EFFICIENCY_REVIEW
A1: review_id | B1: area | C1: decision | D1: action | E1: remaining_validation | F1: status
A2: EFF-01 | B2: PURPOSE | C2: KEEP | D2: Master als kuratiertes Such- und Routingverzeichnis. Keine aktuellen Phasen, Calls oder Deals als Stammdaten. | E2: Live-Befunde separat versionieren. | F2: CLOSED_STRUCTURE
A3: EFF-02 | B3: WORKBOOK | C3: SIMPLIFY | D3: 49 Blaetter zuvor; 18 historische, doppelte oder Reserveblaetter ins Auditarchiv; zwei konzentrierte Pruefuebersichten neu. | E3: Operative Module/IDs/Provenance erhalten. | F3: CLOSED_STRUCTURE
A4: EFF-03 | B4: FIELDS | C4: ARCHIVE | D4: Drei ungenutzte HQ-Felder, leeres MATCH_RULES.rule_id und zwei ungenutzte Seed-Schalter entfernt. | E4: HQ ist kein Nachweis der Antragsregion. Archive erhaelt Werte. | F4: CLOSED_STRUCTURE
A5: EFF-04 | B5: DISCOVERY_ROWS | C5: EXCLUDE_FROM_RUNTIME | D5: 141 M01-Discovery-Profile und ein M05-Discovery-Eintrag bleiben in Excel, nicht im Standard-JSON. | E5: Promote nur nach Quellenpruefung. Unabhaengige Discovery bleibt. | F5: CLOSED_STRUCTURE
A6: EFF-05 | B6: RUNTIME_GRAPH | C6: PRUNE_EXPORT | D6: Runtime enthaelt nur referenzierte Organisationen und Quellen, inkl. Parent-/Canonical-Abhaengigkeiten. | E6: Vollstaendige Registry bleibt in Excel. | F6: CLOSED_STRUCTURE
A7: EFF-06 | B7: BLANK_FIELDS | C7: DISTINGUISH | D7: Alle notwendigen IDs, Verknuepfungen, Prioritaeten und Statusfelder geprueft. Optionale Beziehungen/API-Felder duerfen leer sein. | E7: UNKNOWN bedeutet unbekannt, nicht nicht vorhanden; keine erfundenen Details. | F7: PARTIAL_CONTENT
A8: EFF-07 | B8: FUNDING_GEO | C8: KEEP_AND_FIX | D8: Regionale Auswahl fuer alle 16 Bundeslaender erhalten; EU-Erweiterung von vier auf alle 27 Laendercodes korrigiert. | E8: Region ist Suchscope, keine rechtsverbindliche Foerderfaehigkeit. | F8: CLOSED_ROUTING
A9: EFF-08 | B9: FUNDING_IBT | C9: ADD_TARGETED | D9: IBT Lower Saxony als eine zusaetzliche Forschungs-Translationsroute ergaenzt. | E9: Unterprogramme, Standort, IP/Spinout-Anforderungen und offene Frist live pruefen. | F9: SCOPE_ONLY
A10: EFF-09 | B10: OWN_ASSETS | C10: FIX | D10: Eigene Asset-IDs werden vom Konkurrenzranking getrennt, andere Programme derselben Organisation bleiben moeglich. | E10: Intake muss own_asset_ids liefern; keine automatische Kenntnis privater Projektrollen. | F10: CLOSED_ROUTING
A11: EFF-10 | B11: CLINICAL_PURPOSE | C11: FIX | D11: Praevention, Therapie, Dekolonisierung und Diagnostik getrennt; Endolysine sind keine lebenden Phagen. | E11: Andere Modalitaeten im gleichen klinischen Kontext bleiben beruecksichtigt. | F11: CLOSED_ROUTING
A12: EFF-11 | B12: GENERAL_BREADTH | C12: LIMIT | D12: Maximal fuenf allgemeine M01-Firmenprofile pro Lauf; spezifische Asset-Anker und Must-Watches nicht davon betroffen. | E12: Zurueckstellungen als Coverage Gaps; kein Recall-Nachweis oder Kostenversprechen. | F12: PILOT_POLICY
... A17: EFF-16 | B17: TESTS | C17: SEPARATE | D17: 109 ausgefuehrte technische Checks sowie 11 reale und 13 kontrastierende Projektprofile getrennt dokumentiert. | E17: Tests = lokal; fachliche Vollstaendigkeit und Langdock End-to-End offen. | F17: LOCAL_ONLY

Sheet M01_COMPETITORS
A1: record_id | B1: entity_id | C1: entity_name | D1: record_type | E1: topic_tags | F1: pathogen_tags | G1: indication_tags | H1: modality_tags | I1: search_terms | J1: source_id | K1: base_priority | L1: status | M1: evidence_scope | N1: provenance_id | O1: cautions | P1: source_url | Q1: watch_policy
A2: M01-CMP-02e13c78d23 | B2: CMP-02e13c78d23 | C2: =IFERROR(VLOOKUP(B2,ENTITY_MASTER!$A$2:$B$266,2,FALSE),"") -> Hypharm | D2: COMPANY_WATCH | E2: HAI;ANTIBACTERIAL;AMR | F2: S_AUREUS | G2: NASAL_DECOLONIZATION | H2: ENDOLYSIN;PROTEIN | I2: Hypharm;HY-133;HY133;HYpharm;endolysin;nasal decolonization | J2: SRC-V23-HYPHARM | K2: P1 | L2: ACTIVE | M2: INDEX_PLUS_SOURCE_SCOPE | N2: PR-RAD-CMP-02e13c78d23 | O2: Specific programme scope is in MATCH_ANCHORS; no verified current phase or blanket competitor role. Own-project context supplied by intake. | P2: =IFERROR(IF(VLOOKUP(J2,SOURCE_REGISTRY!$A$2:$E$246,5,FALSE)="","",VLOOKUP(J2,SOURCE_REGISTRY!$A$2:$E$246,5,FALSE)),"") -> https://hypharm.de/phagenlysin-wirkstoff-hy-133-start-der-klinischen-phase-i-first-in-human-studie-zur-eliminierung-von-staphylococcus-aureus-im-nasenmikrobiom/ | Q2: CONDITIONAL
A3: M01-CMP-0c4fb4ab435 | B3: CMP-0c4fb4ab435 | C3: =IFERROR(VLOOKUP(B3,ENTITY_MASTER!$A$2:$B$266,2,FALSE),"") -> AiCuris Anti-infective Cures AG | D3: ENTITY_WATCH | E3: VIRAL;HSV;IMMUNOCOMPROMISED | F3: HSV;BK_POLYOMAVIRUS | G3: HSV_INFECTION | H3: SMALL_MOLECULE;RNA | I3: AiCuris Anti-infective Cures AG | J3: SRC-V2-AICURIS | K3: P1 | L3: ACTIVE | M3: SOURCE_BACKED_SCOPE_NOT_CURRENT_ASSET_STATUS | N3: PR-V2-M01-CMP-0c4fb4ab435 | O3: Projektfit pruefen; nicht automatisch direkter Wettbewerber. | P3: =IFERROR(IF(VLOOKUP(J3,SOURCE_REGISTRY!$A$2:$E$246,5,FALSE)="","",VLOOKUP(J3,SOURCE_REGISTRY!$A$2:$E$246,5,FALSE)),"") -> https://www.aicuris.com/pipeline-products/ | Q3: CONDITIONAL
A4: M01-CMP-0fd9a9b02c5 | B4: CMP-0fd9a9b02c5 | C4: =IFERROR(VLOOKUP(B4,ENTITY_MASTER!$A$2:$B$266,2,FALSE),"") -> Seres Therapeutics Inc | D4: COMPANY_WATCH | E4: HAI;ANTIBACTERIAL;MUCOSAL_INFECTIONS;IMMUNOCOMPROMISED | F4: UNKNOWN | G4: UNKNOWN | H4: MICROBIOME | I4: Seres Therapeutics Inc | J4: SRC-RAD-6f35534e04 | K4: P1 | L4: ACTIVE | M4: GD_SNAPSHOT_PROXY | N4: PR-RAD-CMP-0fd9a9b02c5 | O4: Themen/Modalitaeten sind Suchhinweise. Aktive Assets, Phase, Indikation und Konkurrenzstatus immer live verifizieren. | P4: =IFERROR(IF(VLOOKUP(J4,SOURCE_REGISTRY!$A$2:$E$246,5,FALSE)="","",VLOOKUP(J4,SOURCE_REGISTRY!$A$2:$E$246,5,FALSE)),"") -> https://www.serestherapeutics.com/our-programs/ | Q4: CONDITIONAL
A5: M01-CMP-13b02aead78 | B5: CMP-13b02aead78 | C5: =IFERROR(VLOOKUP(B5,ENTITY_MASTER!$A$2:$B$266,2,FALSE),"") -> Profionics | D5: COMPANY_WATCH | E5: HAI | F5: UNKNOWN | G5: UNKNOWN | H5: DIAGNOSTIC | I5: Profionics | J5: SRC-RAD-dd4d6ddb44 | K5: P1 | L5: ACTIVE | M5: CURATED_SOURCE_ASSOCIATION | N5: PR-RAD-CMP-13b02aead78 | O5: Themen/Modalitaeten sind Suchhinweise. Aktive Assets, Phase, Indikation und Konkurrenzstatus immer live verifizieren. GD-Nullwerte bedeuten fehlende Abdeckung, nicht Nullportfolio. | P5: =IFERROR(IF(VLOOKUP(J5,SOURCE_REGISTRY!$A$2:$E$246,5,FALSE)="","",VLOOKUP(J5,SOURCE_REGISTRY!$A$2:$E$246,5,FALSE)),"") -> https://beam-alliance.eu/members/ | Q5: CONDITIONAL
A6: M01-CMP-1a319a119c8 | B6: CMP-1a319a119c8 | C6: =IFERROR(VLOOKUP(B6,ENTITY_MASTER!$A$2:$B$266,2,FALSE),"") -> Arcturus Therapeutics | D6: COMPANY_WATCH | E6: VIRAL;VACCINE;PANDEMIC;RESPIRATORY | F6: UNKNOWN | G6: UNKNOWN | H6: RNA;VACCINE;PLATFORM | I6: Arcturus Therapeutics | J6: SRC-BD-033 | K6: P1 | L6: ACTIVE | M6: BD_DERIVED_SEARCH_HINT | N6: PR-BD-033 | O6: Ergaenzung aus BD-Katalog; kein Nachweis eines aktuellen konkurrierenden Assets. Primaere Pipeline separat pruefen. | P6: =IFERROR(IF(VLOOKUP(J6,SOURCE_REGISTRY!$A$2:$E$246,5,FALSE)="","",VLOOKUP(J6,SOURCE_REGISTRY!$A$2:$E$246,5,FALSE)),"") -> https://ir.arcturusrx.com/news-releases/news-release-details/arcturus-therapeutics-announces-second-quarter-2026-financial | Q6: CONDITIONAL
A7: M01-CMP-1c39dd558a2 | B7: CMP-1c39dd558a2 | C7: =IFERROR(VLOOKUP(B7,ENTITY_MASTER!$A$2:$B$266,2,FALSE),"") -> Ferring Pharmaceuticals | D7: COMPANY_WATCH | E7: HAI;IMMUNOCOMPROMISED;MICROBIOME | F7: C_DIFFICILE | G7: RECURRENT_CDI | H7: MICROBIOME | I7: Ferring;Rebyota;microbiome | J7: SRC-FERRING | K7: P1 | L7: ACTIVE | M7: SOURCE_BACKED_SCOPE_NOT_CURRENT_ASSET_STATUS | N7: PR-RAD-CMP-1c39dd558a2 | O7: GD active=0 war fehlende GD-Abdeckung; nicht als leere Pipeline verwenden. | P7: =IFERROR(IF(VLOOKUP(J7,SOURCE_REGISTRY!$A$2:$E$246,5,FALSE)="","",VLOOKUP(J7,SOURCE_REGISTRY!$A$2:$E$246,5,FALSE)),"") -> https://www.ferring.com/science-innovation/research-and-development/product-pipeline/ | Q7: CONDITIONAL
A8: M01-CMP-1dc25b959ce | B8: CMP-1dc25b959ce | C8: =IFERROR(VLOOKUP(B8,ENTITY_MASTER!$A$2:$B$266,2,FALSE),"") -> BioNTech | D8: COMPANY_WATCH | E8: HIV;ANTIBACTERIAL;EMERGING_INFECTIONS;TUBERCULOSIS;NTD;MUCOSAL_INFECTIONS | F8: UNKNOWN | G8: UNKNOWN | H8: VACCINE | I8: BioNTech;BioNTech SE | J8: SRC-BD-011 | K8: P1 | L8: ACTIVE | M8: GD_SNAPSHOT_PROXY | N8: PR-RAD-CMP-1dc25b959ce | O8: Themen/Modalitaeten sind Suchhinweise. Aktive Assets, Phase, Indikation und Konkurrenzstatus immer live verifizieren. | P8: =IFERROR(IF(VLOOKUP(J8,SOURCE_REGISTRY!$A$2:$E$246,5,FALSE)="","",VLOOKUP(J8,SOURCE_REGISTRY!$A$2:$E$246,5,FALSE)),"") -> https://www.biontech.com/us/en/home/research-and-innovation/therapeutic-areas/infectious-diseases.html | Q8: CONDITIONAL
A9: M01-CMP-24531a6b01f | B9: CMP-24531a6b01f | C9: =IFERROR(VLOOKUP(B9,ENTITY_MASTER!$A$2:$B$266,2,FALSE),"") -> Moderna | D9: COMPANY_WATCH | E9: HIV;EMERGING_INFECTIONS;MUCOSAL_INFECTIONS;IMMUNOCOMPROMISED;VIRAL;VACCINE | F9: EBV | G9: INFECTIOUS_MONONUCLEOSIS | H9: VACCINE;MRNA_VACCINE | I9: Moderna;Moderna Inc;mRNA-1189;Epstein-Barr vaccine | J9: SRC-BD-012 | K9: P1 | L9: ACTIVE | M9: INDEX_PLUS_SOURCE_SCOPE | N9: PR-RAD-CMP-24531a6b01f | O9: Specific programme scope is in MATCH_ANCHORS; no verified current phase or blanket competitor role. Own-project context supplied by intake. | P9: =IFERROR(IF(VLOOKUP(J9,SOURCE_REGISTRY!$A$2:$E$246,5,FALSE)="","",VLOOKUP(J9,SOURCE_REGISTRY!$A$2:$E$246,5,FALSE)),"") -> https://www.modernatx.com/research/product-pipeline | Q9: CONDITIONAL
A10: M01-CMP-272f19fd220 | B10: CMP-272f19fd220 | C10: =IFERROR(VLOOKUP(B10,ENTITY_MASTER!$A$2:$B$266,2,FALSE),"") -> Serum Institute of India | D10: COMPANY_WATCH | E10: ANTIBACTERIAL;EMERGING_INFECTIONS;TUBERCULOSIS;NTD | F10: UNKNOWN | G10: UNKNOWN | H10: VACCINE;ANTIBODY | I10: Serum Institute of India;Serum Institute of India Pvt Ltd;SII | J10: SRC-BD-018 | K10: P1 | L10: ACTIVE | M10: GD_SNAPSHOT_PROXY | N10: PR-RAD-CMP-272f19fd220 | O10: Themen/Modalitaeten sind Suchhinweise. Aktive Assets, Phase, Indikation und Konkurrenzstatus immer live verifizieren. | P10: =IFERROR(IF(VLOOKUP(J10,SOURCE_REGISTRY!$A$2:$E$246,5,FALSE)="","",VLOOKUP(J10,SOURCE_REGISTRY!$A$2:$E$246,5,FALSE)),"") -> https://www.seruminstitute.com/gates-medical-research-institute-and-the-serum-institute-of-india-reach-agreement.php | Q10: CONDITIONAL
A11: M01-CMP-2e66edddf5d | B11: CMP-2e66edddf5d | C11: =IFERROR(VLOOKUP(B11,ENTITY_MASTER!$A$2:$B$266,2,FALSE),"") -> Vedanta Biosciences Inc | D11: COMPANY_WATCH | E11: HAI;ANTIBACTERIAL;IMMUNOCOMPROMISED | F11: UNKNOWN | G11: UNKNOWN | H11: MICROBIOME | I11: Vedanta Biosciences Inc | J11: SRC-RAD-d19726318a | K11: P1 | L11: ACTIVE | M11: GD_SNAPSHOT_PROXY | N11: PR-RAD-CMP-2e66edddf5d | O11: Themen/Modalitaeten sind Suchhinweise. Aktive Assets, Phase, Indikation und Konkurrenzstatus immer live verifizieren. | P11: =IFERROR(IF(VLOOKUP(J11,SOURCE_REGISTRY!$A$2:$E$246,5,FALSE)="","",VLOOKUP(J11,SOURCE_REGISTRY!$A$2:$E$246,5,FALSE)),"") -> https://www.vedantabio.com/pipeline-programs/pipeline/ | Q11: CONDITIONAL
A12: M01-CMP-3150ecd5e02 | B12: CMP-3150ecd5e02 | C12: =IFERROR(VLOOKUP(B12,ENTITY_MASTER!$A$2:$B$266,2,FALSE),"") -> PATH | D12: ENTITY_WATCH | E12: VACCINE;MALARIA;GLOBAL_HEALTH | F12: ANY | G12: ANY | H12: VACCINE;ANTIBODY;DIAGNOSTIC | I12: PATH | J12: SRC-V2-PATH | K12: P1 | L12: ACTIVE | M12: PUBLIC_SCOPE_NOT_LIVE_ASSET | N12: PR-V2-M01-CMP-3150ecd5e02 | O12: Projektfit pruefen; nicht automatisch direkter Wettbewerber. | P12: =IFERROR(IF(VLOOKUP(J12,SOURCE_REGISTRY!$A$2:$E$246,5,FALSE)="","",VLOOKUP(J12,SOURCE_REGISTRY!$A$2:$E$246,5,FALSE)),"") -> https://www.path.org/who-we-are/programs/center-for-vaccine-innovation-and-access/ | Q12: CONDITIONAL
A13: M01-CMP-335ff7e594c | B13: CMP-335ff7e594c | C13: =IFERROR(VLOOKUP(B13,ENTITY_MASTER!$A$2:$B$266,2,FALSE),"") -> Pfizer | D13: COMPANY_WATCH | E13: HAI;ANTIBACTERIAL;EMERGING_INFECTIONS;MUCOSAL_INFECTIONS | F13: UNKNOWN | G13: UNKNOWN | H13: VACCINE | I13: Pfizer;infectious diseases;vaccines | J13: SRC-PFIZER-PIPE | K13: P1 | L13: ACTIVE | M13: INDEX_PLUS_SOURCE_SCOPE | N13: PR-RAD-CMP-335ff7e594c | O13: Keine konkrete Konkurrenzklassifikation oder aktuelle Phase ableiten; andere Modalitaeten nicht pauschal ausschliessen. | P13: =IFERROR(IF(VLOOKUP(J13,SOURCE_REGISTRY!$A$2:$E$246,5,FALSE)="","",VLOOKUP(J13,SOURCE_REGISTRY!$A$2:$E$246,5,FALSE)),"") -> https://www.pfizer.com/science/drug-product-pipeline | Q13: CONDITIONAL
... A245: M01-CMP-fce0f58579d | B245: CMP-fce0f58579d | C245: =IFERROR(VLOOKUP(B245,ENTITY_MASTER!$A$2:$B$266,2,FALSE),"") -> Immorna Hangzhou Biotechnology Co Ltd | D245: COMPANY_WATCH | E245: EMERGING_INFECTIONS;MUCOSAL_INFECTIONS;IMMUNOCOMPROMISED | F245: UNKNOWN | G245: UNKNOWN | H245: UNKNOWN | I245: Immorna Hangzhou Biotechnology Co Ltd | J245: SRC-NAME-SEARCH | K245: P2 | L245: ACTIVE | M245: DISCOVERY_CANDIDATE_UNVERIFIED | N245: PR-RAD-CMP-fce0f58579d | O245: Themen/Modalitaeten sind Suchhinweise. Aktive Assets, Phase, Indikation und Konkurrenzstatus immer live verifizieren. Kein bestaetigter Primaer-URL im Input; Namenssuche vorgesehen. | P245: =IFERROR(IF(VLOOKUP(J245,SOURCE_REGISTRY!$A$2:$E$246,5,FALSE)="","",VLOOKUP(J245,SOURCE_REGISTRY!$A$2:$E$246,5,FALSE)),"") | Q245: DISCOVERY

Sheet M02_CLINICAL
A1: record_id | B1: record_name | C1: record_type | D1: scope_note | E1: topic_tags | F1: pathogen_tags | G1: modality_tags | H1: jurisdiction_tags | I1: query_class | J1: source_id | K1: base_priority | L1: watch_policy | M1: status | N1: catalog_review_on | O1: source_url | P1: cautions
A2: M02-CTG | B2: ClinicalTrials.gov API | C2: SOURCE_WATCH | D2: REGISTRY_API_DOCS | E2: ANY | F2: ANY | G2: ANY | H2: GLOBAL | I2: M02_REGISTRY | J2: SRC-V2-CTG | K2: P1 | L2: CORE | M2: ACTIVE | N2: 2026-10-29 | O2: =IFERROR(IF(VLOOKUP(J2,SOURCE_REGISTRY!$A$2:$E$246,5,FALSE)="","",VLOOKUP(J2,SOURCE_REGISTRY!$A$2:$E$246,5,FALSE)),"") -> https://clinicaltrials.gov/data-api/api | P2: Registerroute; API und Pagination im Langdock-Workspace noch nicht getestet.
A3: M02-CTIS | B3: EMA CTIS public information | C3: SOURCE_WATCH | D3: EU_REGISTRY_ROUTE | E3: ANY | F3: ANY | G3: ANY | H3: EU | I3: M02_REGISTRY | J3: SRC-V2-CTIS | K3: P1 | L3: CORE | M3: ACTIVE | N3: 2026-10-29 | O3: =IFERROR(IF(VLOOKUP(J3,SOURCE_REGISTRY!$A$2:$E$246,5,FALSE)="","",VLOOKUP(J3,SOURCE_REGISTRY!$A$2:$E$246,5,FALSE)),"") -> https://euclinicaltrials.eu/ | P3: EU/EEA-Studien. Oeffentliches Portal ueber offizielle EMA-Seite aufrufen; keine freie API unterstellen.
A4: M02-ICTRP | B4: WHO ICTRP | C4: SOURCE_WATCH | D4: GLOBAL_REGISTRY_AGGREGATOR | E4: ANY | F4: ANY | G4: ANY | H4: GLOBAL | I4: M02_REGISTRY | J4: SRC-V2-ICTRP | K4: P1 | L4: CORE | M4: ACTIVE | N4: 2026-10-29 | O4: =IFERROR(IF(VLOOKUP(J4,SOURCE_REGISTRY!$A$2:$E$246,5,FALSE)="","",VLOOKUP(J4,SOURCE_REGISTRY!$A$2:$E$246,5,FALSE)),"") -> https://trialsearch.who.int/ | P4: Internationaler Aggregator; Dubletten ueber Register-IDs zusammenfuehren; Zugriffsbedingungen beachten.
A5: M02-V21-DRKS | B5: DRKS | C5: SOURCE_ANCHOR | D5: Register search; study ID and secondary IDs available. Search execution and pagination not tested in Langdock. | E5: ANY | F5: ANY | G5: ANY | H5: ANY | I5: M02_REGISTRY | J5: SRC-V21-DRKS | K5: P0 | L5: CONDITIONAL | M5: ACTIVE | N5: 2026-10-29 | O5: =IFERROR(IF(VLOOKUP(J5,SOURCE_REGISTRY!$A$2:$E$246,5,FALSE)="","",VLOOKUP(J5,SOURCE_REGISTRY!$A$2:$E$246,5,FALSE)),"") -> https://drks.de/search/de | P5: Reference source only. No module activation and no live evidence implied.
A6: M02-V21-DZIF_CTU | B6: DZIF CTU register entry | C6: SOURCE_ANCHOR | D6: Public entry page only. Full use/downloads may require DZIF SSO; do not infer public bulk access. | E6: ANY | F6: ANY | G6: ANY | H6: ANY | I6: M02_REGISTRY | J6: SRC-V21-DZIF_CTU | K6: P1 | L6: CONDITIONAL | M6: ACTIVE | N6: 2026-10-29 | O6: =IFERROR(IF(VLOOKUP(J6,SOURCE_REGISTRY!$A$2:$E$246,5,FALSE)="","",VLOOKUP(J6,SOURCE_REGISTRY!$A$2:$E$246,5,FALSE)),"") -> https://dt-hub.dzif.de/anwendungsfaelle | P6: DZIF SSO/full-use permissions unresolved; never treat inaccessible data as no trials.

Sheet M03_SCI_TECH
A1: record_id | B1: record_name | C1: record_type | D1: scope_note | E1: topic_tags | F1: pathogen_tags | G1: modality_tags | H1: jurisdiction_tags | I1: query_class | J1: source_id | K1: base_priority | L1: watch_policy | M1: status | N1: catalog_review_on | O1: source_url | P1: cautions
A2: M03-PUBMED | B2: NCBI E-utilities | C2: SOURCE_WATCH | D2: LITERATURE_API_DOCS | E2: ANY | F2: ANY | G2: ANY | H2: GLOBAL | I2: M03_LITERATURE | J2: SRC-V2-PUBMED | K2: P1 | L2: CORE | M2: ACTIVE | N2: 2026-10-29 | O2: =IFERROR(IF(VLOOKUP(J2,SOURCE_REGISTRY!$A$2:$E$246,5,FALSE)="","",VLOOKUP(J2,SOURCE_REGISTRY!$A$2:$E$246,5,FALSE)),"") -> https://pubmed.ncbi.nlm.nih.gov/ | P2: PubMed und PMC APIs; API-Limits/Batching beachten; keine Volltextlizenz aus Metadatenzugriff ableiten.
A3: M03-EPMC | B3: Europe PMC REST API | C3: SOURCE_WATCH | D3: LITERATURE_API_DOCS | E3: ANY | F3: ANY | G3: ANY | H3: GLOBAL | I3: M03_LITERATURE | J3: SRC-V2-EPMC | K3: P1 | L3: CORE | M3: ACTIVE | N3: 2026-10-29 | O3: =IFERROR(IF(VLOOKUP(J3,SOURCE_REGISTRY!$A$2:$E$246,5,FALSE)="","",VLOOKUP(J3,SOURCE_REGISTRY!$A$2:$E$246,5,FALSE)),"") -> https://europepmc.org/RestfulWebService | P3: Produktiver REST-Dienst bei ebi.ac.uk dokumentiert; Guide-Abruf hier 403, offizielle Dev-Dokumentation gegengeprueft. Preprints gesondert markieren.
A4: M03-V21-CORDIS | B4: CORDIS academic and consortium research | C4: SOURCE_ANCHOR | D4: Academic and early-development consortium discovery; project records do not prove an active commercial pipeline. | E4: ANY | F4: ANY | G4: ANY | H4: ANY | I4: M03_LITERATURE | J4: SRC-V21-CORDIS | K4: P1 | L4: CONDITIONAL | M4: ACTIVE | N4: 2026-10-29 | O4: =IFERROR(IF(VLOOKUP(J4,SOURCE_REGISTRY!$A$2:$E$246,5,FALSE)="","",VLOOKUP(J4,SOURCE_REGISTRY!$A$2:$E$246,5,FALSE)),"") -> https://cordis.europa.eu/projects | P4: Reference source only. No module activation and no live evidence implied.

Sheet M04_REGULATORY
A1: record_id | B1: record_name | C1: record_type | D1: scope_note | E1: topic_tags | F1: pathogen_tags | G1: modality_tags | H1: jurisdiction_tags | I1: query_class | J1: source_id | K1: base_priority | L1: watch_policy | M1: status | N1: catalog_review_on | O1: source_url | P1: cautions
A2: M04-EMA_GUIDE | B2: EMA scientific guidelines | C2: SOURCE_WATCH | D2: REGULATORY_GUIDELINE_HUB | E2: ANY | F2: ANY | G2: ANY | H2: EU | I2: M04_GUIDANCE | J2: SRC-V2-EMA_GUIDE | K2: P1 | L2: CORE | M2: ACTIVE | N2: 2026-10-29 | O2: =IFERROR(IF(VLOOKUP(J2,SOURCE_REGISTRY!$A$2:$E$246,5,FALSE)="","",VLOOKUP(J2,SOURCE_REGISTRY!$A$2:$E$246,5,FALSE)),"") -> https://www.ema.europa.eu/en/human-regulatory-overview/research-development/scientific-guidelines-human-medicines | P2: Version, Draft/Final, Gueltigkeitsdatum und Produktklasse live pruefen. Keine vertraulichen Scientific-Advice-Protokolle erwarten.
A3: M04-FDA_GUIDE | B3: FDA guidance documents | C3: SOURCE_WATCH | D3: FDA_GUIDELINE_HUB | E3: ANY | F3: ANY | G3: ANY | H3: US | I3: M04_GUIDANCE | J3: SRC-V2-FDA_GUIDE | K3: P1 | L3: CORE | M3: ACTIVE | N3: 2026-10-29 | O3: =IFERROR(IF(VLOOKUP(J3,SOURCE_REGISTRY!$A$2:$E$246,5,FALSE)="","",VLOOKUP(J3,SOURCE_REGISTRY!$A$2:$E$246,5,FALSE)),"") -> https://www.fda.gov/regulatory-information/search-fda-guidance-documents | P3: Filter nach Produkttyp, Ausgabedatum und Draft/Final; Tabelleninhalt dynamisch.
A4: M04-EMA_MED | B4: EMA medicines | C4: SOURCE_WATCH | D4: AUTHORIZATION_ROUTE | E4: ANY | F4: ANY | G4: ANY | H4: EU | I4: M04_GUIDANCE | J4: SRC-V2-EMA_MED | K4: P1 | L4: CORE | M4: ACTIVE | N4: 2026-10-29 | O4: =IFERROR(IF(VLOOKUP(J4,SOURCE_REGISTRY!$A$2:$E$246,5,FALSE)="","",VLOOKUP(J4,SOURCE_REGISTRY!$A$2:$E$246,5,FALSE)),"") -> https://www.ema.europa.eu/en/medicines | P4: EPAR, oeffentliche Bewertungen und Zulassungsentscheidungen; nicht vollstaendig fuer nationale Zulassungen.
A5: M04-EMA_ATMP | B5: EMA investigational ATMP guideline | C5: SOURCE_WATCH | D5: ATMP_GUIDELINE_ROUTE | E5: ANY | F5: ANY | G5: CELL_GENE_THERAPY;CELL_THERAPY;GENE_THERAPY | H5: EU | I5: M04_GUIDANCE | J5: SRC-V2-EMA_ATMP | K5: P1 | L5: CONDITIONAL | M5: ACTIVE | N5: 2026-10-29 | O5: =IFERROR(IF(VLOOKUP(J5,SOURCE_REGISTRY!$A$2:$E$246,5,FALSE)="","",VLOOKUP(J5,SOURCE_REGISTRY!$A$2:$E$246,5,FALSE)),"") -> https://www.ema.europa.eu/en/scientific-guidelines/guideline-quality-non-clinical-clinical-requirements-investigational-advanced-therapy-medicinal-products-clinical-trials | P5: Zell-/Gentherapie; einschlaegige Version und Umsetzungsdatum pruefen.
A6: M04-FDA_CGT | B6: FDA cellular and gene therapy guidance | C6: SOURCE_WATCH | D6: CGT_GUIDELINE_ROUTE | E6: ANY | F6: ANY | G6: CELL_GENE_THERAPY;CELL_THERAPY;GENE_THERAPY | H6: US | I6: M04_GUIDANCE | J6: SRC-V2-FDA_CGT | K6: P1 | L6: CONDITIONAL | M6: ACTIVE | N6: 2026-10-29 | O6: =IFERROR(IF(VLOOKUP(J6,SOURCE_REGISTRY!$A$2:$E$246,5,FALSE)="","",VLOOKUP(J6,SOURCE_REGISTRY!$A$2:$E$246,5,FALSE)),"") -> https://www.fda.gov/vaccines-blood-biologics/biologics-guidances/cellular-gene-therapy-guidances | P6: CBER-Zell-/Gentherapie; produkt- und risikospezifische Anforderungen.
A7: M04-PEI | B7: PEI regulation | C7: SOURCE_WATCH | D7: GERMAN_BIOLOGICS_REGULATION | E7: ANY | F7: ANY | G7: VACCINE;ANTIBODY;CELL_GENE_THERAPY;CELL_THERAPY;GENE_THERAPY | H7: DE | I7: M04_GUIDANCE | J7: SRC-V2-PEI | K7: P1 | L7: CONDITIONAL | M7: ACTIVE | N7: 2026-10-29 | O7: =IFERROR(IF(VLOOKUP(J7,SOURCE_REGISTRY!$A$2:$E$246,5,FALSE)="","",VLOOKUP(J7,SOURCE_REGISTRY!$A$2:$E$246,5,FALSE)),"") -> https://www.pei.de/EN/regulation/regulation-node.html | P7: Biologics source hub, not a blanket classification for all phages/microbiome products; authority responsibility is product-specific. Access still untested in Langdock.
A8: M04-EU_IVDR | B8: EU MDR / IVDR framework | C8: SOURCE_WATCH | D8: IVD_REGULATORY_ROUTE | E8: ANY | F8: ANY | G8: DIAGNOSTIC | H8: EU | I8: M04_GUIDANCE | J8: SRC-V2-EU_IVDR | K8: P1 | L8: CONDITIONAL | M8: ACTIVE | N8: 2026-10-29 | O8: =IFERROR(IF(VLOOKUP(J8,SOURCE_REGISTRY!$A$2:$E$246,5,FALSE)="","",VLOOKUP(J8,SOURCE_REGISTRY!$A$2:$E$246,5,FALSE)),"") -> https://health.ec.europa.eu/medical-devices-new-regulations_en | P8: MDR und IVDR getrennt von Arzneimittelregulierung; Produktklassifikation und aktuelle Uebergangsregeln pruefen.
A9: M04-EMA_PHAGE | B9: EMA phage quality guideline | C9: SOURCE_WATCH | D9: PHAGE_QUALITY_GUIDELINE | E9: ANY | F9: ANY | G9: PHAGE | H9: EU | I9: M04_GUIDANCE | J9: SRC-V2-EMA_PHAGE | K9: P1 | L9: CONDITIONAL | M9: ACTIVE | N9: 2026-10-29 | O9: =IFERROR(IF(VLOOKUP(J9,SOURCE_REGISTRY!$A$2:$E$246,5,FALSE)="","",VLOOKUP(J9,SOURCE_REGISTRY!$A$2:$E$246,5,FALSE)),"") -> https://www.ema.europa.eu/en/scientific-guidelines/quality-aspects-phage-therapy-medicinal-products | P9: Offizielle Seite zeigt Draft / consultation closed; nicht als finale verbindliche Leitlinie ausgeben.
A10: M04-FDA_LBP | B10: FDA live biotherapeutic CMC guidance | C10: SOURCE_WATCH | D10: LIVE_BIOTHERAPEUTIC_CMC | E10: ANY | F10: ANY | G10: MICROBIOME | H10: US | I10: M04_GUIDANCE | J10: SRC-V2-FDA_LBP | K10: P1 | L10: CONDITIONAL | M10: ACTIVE | N10: 2026-10-29 | O10: =IFERROR(IF(VLOOKUP(J10,SOURCE_REGISTRY!$A$2:$E$246,5,FALSE)="","",VLOOKUP(J10,SOURCE_REGISTRY!$A$2:$E$246,5,FALSE)),"") -> https://www.fda.gov/regulatory-information/search-fda-guidance-documents/early-clinical-trials-live-biotherapeutic-products-chemistry-manufacturing-and-control-information | P10: FDA-Route fuer Live Biotherapeutic Products. Nicht automatisch auf Gentherapie-Vektoren anwendbar.
A11: M04-BFARM | B11: BfArM clinical trials / medicinal products | C11: SOURCE_WATCH | D11: GERMAN_MEDICINAL_PRODUCT_REGULATION | E11: ANY | F11: ANY | G11: SMALL_MOLECULE;PHAGE;ENDOLYSIN;PEPTIDE;MICROBIOME | H11: DE | I11: M04_GUIDANCE | J11: SRC-V23-BFARM | K11: P1 | L11: CONDITIONAL | M11: ACTIVE | N11: 2026-10-29 | O11: =IFERROR(IF(VLOOKUP(J11,SOURCE_REGISTRY!$A$2:$E$246,5,FALSE)="","",VLOOKUP(J11,SOURCE_REGISTRY!$A$2:$E$246,5,FALSE)),"") -> https://www.bfarm.de/DE/Arzneimittel/Klinische-Pruefung/_node.html | P11: Official source blocked here (403). Product classification and German authority responsibility require product-specific confirmation. Not an automatic PEI/BfArM determination.

Sheet M05_FUNDING
A1: record_id | B1: record_name | C1: record_type | D1: applicant_types | E1: region_scope | F1: institution_scope | G1: trigger_tags | H1: required_context_tags | I1: development_scope | J1: activity_tags | K1: routing_mode | L1: source_id | M1: base_priority | N1: status | O1: eligibility_note | P1: provenance_id | Q1: source_url | R1: parent_record_id | S1: context_match | T1: watch_policy
A2: DE_FDB | B2: Förderdatenbank Bund / Länder / EU | C2: PORTAL | D2: ANY | E2: DE | F2: ANY | G2: ANY | H2: ANY | I2: ANY | J2: ANY | K2: BASELINE | L2: SRC-DE_FDB | M2: P1 | N2: ACTIVE | O2: Bund/Laender/EU-Einstieg; keine pauschale Foerderfaehigkeit. | P2: PR-FUND-DE_FDB | Q2: =IFERROR(IF(VLOOKUP(L2,SOURCE_REGISTRY!$A$2:$E$246,5,FALSE)="","",VLOOKUP(L2,SOURCE_REGISTRY!$A$2:$E$246,5,FALSE)),"") -> https://www.foerderdatenbank.de/FDB/DE/Foerderprogramme/foerderprogramme.html | S2: ANY | T2: CORE
A3: DE_BMFTR_HEALTH | B3: BMFTR Gesundheitsforschung - Bekanntmachungen | C3: PORTAL | D3: ACADEMIA;PUBLIC_BODY;CONSORTIUM | E3: DE | F3: ANY | G3: ANY | H3: ANY | I3: ANY | J3: ANY | K3: BASELINE | L3: SRC-DE_BMFTR_HEALTH | M3: P1 | N3: ACTIVE | O3: Suchquelle, kein bestaetigter offener Call. Antragsteller, Konsortium, Standort und Bedingungen pro Ausschreibung pruefen. | P3: PR-FUND-DE_BMFTR_HEALTH | Q3: =IFERROR(IF(VLOOKUP(L3,SOURCE_REGISTRY!$A$2:$E$246,5,FALSE)="","",VLOOKUP(L3,SOURCE_REGISTRY!$A$2:$E$246,5,FALSE)),"") -> https://www.gesundheitsforschung-bmftr.de/de/bekanntmachungen-5786.php | S3: ANY | T3: CORE
A4: DE_DFG | B4: DFG Förderprogramme | C4: PORTAL | D4: ACADEMIA | E4: DE | F4: ANY | G4: BASIC;CLINICAL;HEALTH | H4: ANY | I4: DISCOVERY;PRECLINICAL;PHASE_1;PHASE_2;PHASE_3 | J4: CLINICAL | K4: MATCH | L4: SRC-DE_DFG | M4: P2 | N4: ACTIVE | O4: Suchquelle, kein bestaetigter offener Call. Antragsteller, Konsortium, Standort und Bedingungen pro Ausschreibung pruefen. | P4: PR-FUND-DE_DFG | Q4: =IFERROR(IF(VLOOKUP(L4,SOURCE_REGISTRY!$A$2:$E$246,5,FALSE)="","",VLOOKUP(L4,SOURCE_REGISTRY!$A$2:$E$246,5,FALSE)),"") -> https://www.dfg.de/de/foerderung/foerdermoeglichkeiten/programme | S4: ANY | T4: CONDITIONAL
A5: DE_DFG_CLINICAL | B5: DFG Klinische Studien | C5: PROGRAMME | D5: ACADEMIA | E5: DE | F5: ANY | G5: CLINICAL | H5: ANY | I5: PHASE_1;PHASE_2;PHASE_3 | J5: CLINICAL | K5: MATCH | L5: SRC-DE_DFG_CLINICAL | M5: P2 | N5: ACTIVE | O5: Suchquelle, kein bestaetigter offener Call. Antragsteller, Konsortium, Standort und Bedingungen pro Ausschreibung pruefen. | P5: PR-FUND-DE_DFG_CLINICAL | Q5: =IFERROR(IF(VLOOKUP(L5,SOURCE_REGISTRY!$A$2:$E$246,5,FALSE)="","",VLOOKUP(L5,SOURCE_REGISTRY!$A$2:$E$246,5,FALSE)),"") -> https://www.dfg.de/de/foerderung/foerdermoeglichkeiten/programme/einzelfoerderung/klinische-studien | S5: ANY | T5: CONDITIONAL
A6: DE_FORTRA | B6: EKFS / ForTra Translatorik | C6: PROGRAMME | D6: ACADEMIA;PUBLIC_BODY | E6: DE | F6: ANY | G6: TRANSLATION;THERAPEUTICS;DIAGNOSTICS;MEDTECH | H6: ANY | I6: PRECLINICAL;PHASE_1 | J6: CMC | K6: MATCH | L6: SRC-DE_FORTRA | M6: P1 | N6: ACTIVE | O6: Translatorische Programmfamilie; konkrete Ausschreibung und Eligibility bleiben live. | P6: PR-FUND-DE_FORTRA | Q6: =IFERROR(IF(VLOOKUP(L6,SOURCE_REGISTRY!$A$2:$E$246,5,FALSE)="","",VLOOKUP(L6,SOURCE_REGISTRY!$A$2:$E$246,5,FALSE)),"") -> https://ekfs.de/wissenschaftliche-foerderung/Translatorik-ForTra/Foerderverfahren | S6: ANY | T6: CONDITIONAL
A7: DE_EKFS_CALLS | B7: EKFS Ausschreibungskalender | C7: PORTAL | D7: ACADEMIA;PUBLIC_BODY | E7: DE | F7: ANY | G7: HEALTH;CLINICAL;TRANSLATION | H7: ANY | I7: ANY | J7: ANY | K7: MATCH | L7: SRC-DE_EKFS_CALLS | M7: P2 | N7: ACTIVE | O7: Suchquelle, kein bestaetigter offener Call. Antragsteller, Konsortium, Standort und Bedingungen pro Ausschreibung pruefen. | P7: PR-FUND-DE_EKFS_CALLS | Q7: =IFERROR(IF(VLOOKUP(L7,SOURCE_REGISTRY!$A$2:$E$246,5,FALSE)="","",VLOOKUP(L7,SOURCE_REGISTRY!$A$2:$E$246,5,FALSE)),"") -> https://ekfs.de/en/current-topics/funding-application-calender | S7: ANY | T7: CONDITIONAL
A8: DE_GO_BIO | B8: GO-Bio next | C8: PROGRAMME | D8: ACADEMIA;SPINOUT | E8: DE | F8: ANY | G8: TRANSLATION;COMMERCIALIZATION | H8: ANY | I8: PRECLINICAL;DISCOVERY;LEAD | J8: CMC | K8: MATCH | L8: SRC-DE_GO_BIO | M8: P2 | N8: ACTIVE | O8: Suchquelle, kein bestaetigter offener Call. Antragsteller, Konsortium, Standort und Bedingungen pro Ausschreibung pruefen. | P8: PR-FUND-DE_GO_BIO | Q8: =IFERROR(IF(VLOOKUP(L8,SOURCE_REGISTRY!$A$2:$E$246,5,FALSE)="","",VLOOKUP(L8,SOURCE_REGISTRY!$A$2:$E$246,5,FALSE)),"") -> https://www.foerderdatenbank.de/FDB/Content/DE/Foerderprogramm/Bund/BMBF/go-bio-next.html | S8: ANY | T8: CONDITIONAL
A9: DE_KMU_BIOMED | B9: KMU-innovativ Biomedizin | C9: PROGRAMME | D9: SME;CONSORTIUM | E9: DE | F9: ANY | G9: HEALTH;THERAPEUTICS;DIAGNOSTICS;MEDTECH | H9: ANY | I9: PRECLINICAL;PHASE_1;PHASE_2;PHASE_3 | J9: CMC;CLINICAL | K9: MATCH | L9: SRC-DE_KMU_BIOMED | M9: P2 | N9: ACTIVE | O9: Suchquelle, kein bestaetigter offener Call. Antragsteller, Konsortium, Standort und Bedingungen pro Ausschreibung pruefen. | P9: PR-FUND-DE_KMU_BIOMED | Q9: =IFERROR(IF(VLOOKUP(L9,SOURCE_REGISTRY!$A$2:$E$246,5,FALSE)="","",VLOOKUP(L9,SOURCE_REGISTRY!$A$2:$E$246,5,FALSE)),"") -> https://www.foerderdatenbank.de/FDB/Content/DE/Foerderprogramm/Bund/BMBF/biomedizin.html | S9: ANY | T9: CONDITIONAL
A10: DE_ZIM | B10: ZIM - Zentrales Innovationsprogramm Mittelstand | C10: PROGRAMME | D10: SME;CONSORTIUM | E10: DE | F10: ANY | G10: INNOVATION;COMMERCIALIZATION | H10: ANY | I10: DISCOVERY;LEAD;PRECLINICAL | J10: CMC | K10: MATCH | L10: SRC-DE_ZIM | M10: P2 | N10: ACTIVE | O10: Suchquelle, kein bestaetigter offener Call. Antragsteller, Konsortium, Standort und Bedingungen pro Ausschreibung pruefen. | P10: PR-FUND-DE_ZIM | Q10: =IFERROR(IF(VLOOKUP(L10,SOURCE_REGISTRY!$A$2:$E$246,5,FALSE)="","",VLOOKUP(L10,SOURCE_REGISTRY!$A$2:$E$246,5,FALSE)),"") -> https://www.zim.de/ | S10: ANY | T10: CONDITIONAL
A11: DE_EXIST | B11: EXIST | C11: PROGRAMME | D11: ACADEMIA;SPINOUT | E11: DE | F11: ANY | G11: SPINOUT;COMMERCIALIZATION | H11: ANY | I11: DISCOVERY;LEAD;PRECLINICAL | J11: ANY | K11: MATCH | L11: SRC-DE_EXIST | M11: P2 | N11: REVIEW | O11: Suchquelle, kein bestaetigter offener Call. Antragsteller, Konsortium, Standort und Bedingungen pro Ausschreibung pruefen. | P11: PR-FUND-DE_EXIST | Q11: =IFERROR(IF(VLOOKUP(L11,SOURCE_REGISTRY!$A$2:$E$246,5,FALSE)="","",VLOOKUP(L11,SOURCE_REGISTRY!$A$2:$E$246,5,FALSE)),"") -> https://www.exist.de/ | S11: ANY | T11: CONDITIONAL
A12: DE_VW_STIFTUNG | B12: VolkswagenStiftung - Förderangebote | C12: FOUNDATION | D12: ACADEMIA | E12: DE | F12: ANY | G12: BASIC;HEALTH;INNOVATION | H12: ANY | I12: DISCOVERY;PRECLINICAL | J12: ANY | K12: MATCH | L12: SRC-DE_VW_STIFTUNG | M12: P2 | N12: REVIEW | O12: Suchquelle, kein bestaetigter offener Call. Antragsteller, Konsortium, Standort und Bedingungen pro Ausschreibung pruefen. | P12: PR-FUND-DE_VW_STIFTUNG | Q12: =IFERROR(IF(VLOOKUP(L12,SOURCE_REGISTRY!$A$2:$E$246,5,FALSE)="","",VLOOKUP(L12,SOURCE_REGISTRY!$A$2:$E$246,5,FALSE)),"") -> https://www.volkswagenstiftung.de/de/foerderung | S12: ANY | T12: CONDITIONAL
A13: DE_DZIF_INTERNAL | B13: DZIF interne Projekt- und Transferförderung | C13: INSTITUTION | D13: ACADEMIA;PUBLIC_BODY | E13: DE | F13: DZIF | G13: INSTITUTION;TRANSLATION;HEALTH | H13: ANY | I13: ANY | J13: ANY | K13: INSTITUTION | L13: SRC-DE_DZIF_INTERNAL | M13: P1 | N13: REVIEW | O13: Suchquelle, kein bestaetigter offener Call. Antragsteller, Konsortium, Standort und Bedingungen pro Ausschreibung pruefen. Interne Calls ggf. nicht oeffentlich; autorisierte interne Quelle erforderlich. | P13: PR-FUND-DE_DZIF_INTERNAL | Q13: =IFERROR(IF(VLOOKUP(L13,SOURCE_REGISTRY!$A$2:$E$246,5,FALSE)="","",VLOOKUP(L13,SOURCE_REGISTRY!$A$2:$E$246,5,FALSE)),"") -> https://www.dzif.de/ | S13: ANY | T13: CONDITIONAL
... A52: DE_GO_BIO_INITIAL | B52: GO-Bio initial | C52: PROGRAMME | D52: ACADEMIA;PUBLIC_BODY | E52: DE | F52: ANY | G52: TRANSLATION;BIOTECH;SPINOUT | H52: ANY | I52: DISCOVERY;PRECLINICAL | J52: ANY | K52: MATCH | L52: SRC-V2-GO_BIO_INITIAL | M52: P1 | N52: ACTIVE | O52: Fruehe Verwertungsideen; kein Ersatz fuer GO-Bio next. | P52: PR-V2-DE_GO_BIO_INITIAL | Q52: =IFERROR(IF(VLOOKUP(L52,SOURCE_REGISTRY!$A$2:$E$246,5,FALSE)="","",VLOOKUP(L52,SOURCE_REGISTRY!$A$2:$E$246,5,FALSE)),"") -> https://www.foerderdatenbank.de/FDB/Content/DE/Foerderprogramm/Bund/BMBF/gesundheitsforschung-go-bio-initial2.html | S52: ALL | T52: CONDITIONAL
A53: EU_HORIZON_HEALTH | B53: Horizon Europe Cluster 1 Health | C53: PROGRAMME | D53: ACADEMIA;SME;INDUSTRY;PUBLIC_BODY;CONSORTIUM | E53: EU | F53: ANY | G53: HEALTH;INFECTIOUS_BROAD | H53: ANY | I53: ANY | J53: ANY | K53: MATCH | L53: SRC-EU_FT | M53: P1 | N53: ACTIVE | O53: Topic-, Konsortial- und Laenderbedingungen konkret pruefen; Portal mit EU_FT geteilt. | P53: PR-V2-EU_HORIZON_HEALTH | Q53: =IFERROR(IF(VLOOKUP(L53,SOURCE_REGISTRY!$A$2:$E$246,5,FALSE)="","",VLOOKUP(L53,SOURCE_REGISTRY!$A$2:$E$246,5,FALSE)),"") -> https://ec.europa.eu/info/funding-tenders/opportunities/portal/screen/opportunities/calls-for-proposals | R53: EU_FT | S53: ALL | T53: CONDITIONAL
A54: EU_EIC_PATHFINDER | B54: EIC Pathfinder | C54: PROGRAMME | D54: ACADEMIA;SME;INDUSTRY;CONSORTIUM | E54: EU | F54: ANY | G54: PLATFORM;BIOTECH;BASIC | H54: ANY | I54: DISCOVERY;PRECLINICAL | J54: ANY | K54: MATCH | L54: SRC-V2-EIC_PATHFINDER | M54: P1 | N54: ACTIVE | O54: Open und Challenges haben unterschiedliche Regeln; TRL nicht klinischer Phase gleichsetzen. | P54: PR-V2-EU_EIC_PATHFINDER | Q54: =IFERROR(IF(VLOOKUP(L54,SOURCE_REGISTRY!$A$2:$E$246,5,FALSE)="","",VLOOKUP(L54,SOURCE_REGISTRY!$A$2:$E$246,5,FALSE)),"") -> https://eic.ec.europa.eu/eic-funding-opportunities/eic-pathfinder_en | R54: EU_EIC | S54: ALL | T54: CONDITIONAL
A55: EU_EIC_TRANSITION | B55: EIC Transition | C55: PROGRAMME | D55: ACADEMIA;SME;CONSORTIUM | E55: EU | F55: ANY | G55: TRANSLATION;PLATFORM;BIOTECH | H55: ELIGIBLE_EU_RESULT | I55: ANY | J55: ANY | K55: MATCH | L55: SRC-V2-EIC_TRANSITION | M55: P1 | N55: ACTIVE | O55: Zugelassenes EU-Vorprojektergebnis und Fristfenster zwingend verifizieren. | P55: PR-V2-EU_EIC_TRANSITION | Q55: =IFERROR(IF(VLOOKUP(L55,SOURCE_REGISTRY!$A$2:$E$246,5,FALSE)="","",VLOOKUP(L55,SOURCE_REGISTRY!$A$2:$E$246,5,FALSE)),"") -> https://eic.ec.europa.eu/eic-funding-opportunities/eic-transition_en | R55: EU_EIC | S55: ALL | T55: CONDITIONAL
A56: EU_EIC_ACCELERATOR | B56: EIC Accelerator | C56: PROGRAMME | D56: SME | E56: EU | F56: ANY | G56: SPINOUT;COMMERCIALIZATION;BIOTECH | H56: ANY | I56: ANY | J56: ANY | K56: MATCH | L56: SRC-V2-EIC_ACCELERATOR | M56: P1 | N56: ACTIVE | O56: SME-/Startup- bzw. Gruendungskonstellation, TRL und Grant/Investment-Komponente pro Call pruefen. | P56: PR-V2-EU_EIC_ACCELERATOR | Q56: =IFERROR(IF(VLOOKUP(L56,SOURCE_REGISTRY!$A$2:$E$246,5,FALSE)="","",VLOOKUP(L56,SOURCE_REGISTRY!$A$2:$E$246,5,FALSE)),"") -> https://eic.ec.europa.eu/eic-funding-opportunities/eic-accelerator_en | R56: EU_EIC | S56: ALL | T56: CONDITIONAL
A57: EU_ERC_POC | B57: ERC Proof of Concept | C57: PROGRAMME | D57: ACADEMIA | E57: EU | F57: ANY | G57: TRANSLATION;SPINOUT;COMMERCIALIZATION | H57: ELIGIBLE_ERC_GRANT | I57: ANY | J57: ANY | K57: MATCH | L57: SRC-V2-ERC_POC | M57: P1 | N57: ACTIVE | O57: Kein offenes allgemeines Transferprogramm; Foerderfaehigkeit der ERC-PI-Vorfoerderung pruefen. | P57: PR-V2-EU_ERC_POC | Q57: =IFERROR(IF(VLOOKUP(L57,SOURCE_REGISTRY!$A$2:$E$246,5,FALSE)="","",VLOOKUP(L57,SOURCE_REGISTRY!$A$2:$E$246,5,FALSE)),"") -> https://erc.europa.eu/apply-grant/proof-concept | S57: ALL | T57: CONDITIONAL
A58: US_BARDA_BAA | B58: BARDA BAA | C58: SOLICITATION | D58: ACADEMIA;SME;INDUSTRY;CONSORTIUM | E58: GLOBAL | F58: ANY | G58: PREPAREDNESS;PANDEMIC;AMR | H58: US_MCM_FIT | I58: ANY | J58: ANY | K58: MATCH | L58: SRC-V2-BARDA_BAA | M58: P1 | N58: ACTIVE | O58: US-Bedarfsfit, aktive AOIs, internationale Teilnahme und Vertragsbedingungen pruefen. | P58: PR-V2-US_BARDA_BAA | Q58: =IFERROR(IF(VLOOKUP(L58,SOURCE_REGISTRY!$A$2:$E$246,5,FALSE)="","",VLOOKUP(L58,SOURCE_REGISTRY!$A$2:$E$246,5,FALSE)),"") -> https://www.medicalcountermeasures.gov/barda/barda-baa | S58: ALL | T58: CONDITIONAL
A59: US_BARDA_DRIVE | B59: BARDA DRIVe opportunities | C59: OPPORTUNITIES_PORTAL | D59: ACADEMIA;SME;INDUSTRY;CONSORTIUM | E59: GLOBAL | F59: ANY | G59: PREPAREDNESS;DIAGNOSTICS;PLATFORM | H59: US_MCM_FIT | I59: ANY | J59: ANY | K59: MATCH | L59: SRC-V2-BARDA_DRIVE | M59: P1 | N59: ACTIVE | O59: Kein Always-open-Grant; EZ-BAA derzeit laut separater offizieller Statusroute geschlossen. | P59: PR-V2-US_BARDA_DRIVE | Q59: =IFERROR(IF(VLOOKUP(L59,SOURCE_REGISTRY!$A$2:$E$246,5,FALSE)="","",VLOOKUP(L59,SOURCE_REGISTRY!$A$2:$E$246,5,FALSE)),"") -> https://www.drive.hhs.gov/partner.html | S59: ALL | T59: CONDITIONAL
A60: GL_FIND_PARTNERS | B60: FIND calls for partners | C60: PARTNER_CALL | D60: ACADEMIA;SME;INDUSTRY;PUBLIC_BODY;CONSORTIUM | E60: GLOBAL | F60: ANY | G60: DIAGNOSTICS | H60: ANY | I60: ANY | J60: ANY | K60: MATCH | L60: SRC-V2-FIND | M60: P1 | N60: ACTIVE | O60: Partnerschafts-/Entwicklungsaufruf; Budget und Zuschusscharakter nur bei explizitem Nachweis. | P60: PR-V2-GL_FIND_PARTNERS | Q60: =IFERROR(IF(VLOOKUP(L60,SOURCE_REGISTRY!$A$2:$E$246,5,FALSE)="","",VLOOKUP(L60,SOURCE_REGISTRY!$A$2:$E$246,5,FALSE)),"") -> https://www.finddx.org/about-us/donors-and-partners/calls-for-partners/ | S60: ALL | T60: CONDITIONAL
A61: EU_HERA_OPPORTUNITIES | B61: HERA funding and opportunities | C61: OPPORTUNITIES_PORTAL | D61: ACADEMIA;SME;INDUSTRY;PUBLIC_BODY;CONSORTIUM | E61: EU | F61: ANY | G61: PREPAREDNESS;PANDEMIC;AMR | H61: ANY | I61: ANY | J61: ANY | K61: MATCH | L61: SRC-V2-HERA | M61: P1 | N61: ACTIVE | O61: Forschungsfoerderung, Beschaffung und Bevorratung sind unterschiedliche Instrumente. | P61: PR-V2-EU_HERA_OPPORTUNITIES | Q61: =IFERROR(IF(VLOOKUP(L61,SOURCE_REGISTRY!$A$2:$E$246,5,FALSE)="","",VLOOKUP(L61,SOURCE_REGISTRY!$A$2:$E$246,5,FALSE)),"") -> https://health.ec.europa.eu/health-emergency-preparedness-and-response-hera_en | R61: EU_FT | S61: ALL | T61: CONDITIONAL
A62: INST_BONN_BONFOR | B62: BONFOR - Medizinische Fakultaet Bonn | C62: INSTITUTION | D62: ACADEMIA | E62: DE-NW | F62: UNI_BONN_MED | G62: BASIC;CLINICAL;TRANSLATION | H62: ANY | I62: DISCOVERY;PRECLINICAL | J62: CLINICAL | K62: INSTITUTION | L62: SRC-V22-BONFOR | M62: P2 | N62: ACTIVE | O62: Nur geeignete Angehoerige der Medizinischen Fakultaet Bonn; aktuelle Instrumente, Bewerberstatus und Fristen live pruefen. | P62: PR-V22-INST-BONN-BONFOR | Q62: =IFERROR(IF(VLOOKUP(L62,SOURCE_REGISTRY!$A$2:$E$246,5,FALSE)="","",VLOOKUP(L62,SOURCE_REGISTRY!$A$2:$E$246,5,FALSE)),"") -> https://www.medfak.uni-bonn.de/de/forschung/forschungsfoerderung/bonfor/bonfor-forschungsfoerderprogramm | S62: ALL | T62: CONDITIONAL
A63: INST_TUEBINGEN_FORTUNE | B63: fortuene - Medizinische Fakultaet Tuebingen | C63: INSTITUTION | D63: ACADEMIA | E63: DE-BW | F63: UNI_TUEBINGEN_MED | G63: BASIC;CLINICAL;TRANSLATION | H63: ANY | I63: DISCOVERY;PRECLINICAL | J63: TRANSLATION;CLINICAL | K63: INSTITUTION | L63: SRC-V22-FORTUNE | M63: P2 | N63: ACTIVE | O63: Intramurale Ausschreibungen; eligibles Arbeitsverhaeltnis und Foerderlinie anhand Originalseite pruefen. | P63: PR-V22-INST-TUEBINGEN-FORTUNE | Q63: =IFERROR(IF(VLOOKUP(L63,SOURCE_REGISTRY!$A$2:$E$246,5,FALSE)="","",VLOOKUP(L63,SOURCE_REGISTRY!$A$2:$E$246,5,FALSE)),"") -> https://www.medizin.uni-tuebingen.de/de/medizinische-fakultaet/forschung/forschungsfoerderung | S63: ALL | T63: CONDITIONAL
A64: INST_MHH_HILF | B64: MHH Hochschulinterne Leistungsfoerderung (HiLF) | C64: INSTITUTION | D64: ACADEMIA | E64: DE-NI | F64: MHH | G64: BASIC;CLINICAL;TRANSLATION | H64: ANY | I64: DISCOVERY;PRECLINICAL | J64: CLINICAL | K64: INSTITUTION | L64: SRC-V22-MHH | M64: P2 | N64: ACTIVE | O64: MHH-interne Foerderung; Details nur im Intranet, verbindlicher Zugriff muss vor Antragsplanung geklaert werden. | P64: PR-V22-INST-MHH-HILF | Q64: =IFERROR(IF(VLOOKUP(L64,SOURCE_REGISTRY!$A$2:$E$246,5,FALSE)="","",VLOOKUP(L64,SOURCE_REGISTRY!$A$2:$E$246,5,FALSE)),"") -> https://www.mhh.de/forschung/hochschulinterne-leistungsfoerderung | S64: ALL | T64: CONDITIONAL
A65: INST_HEIDELBERG_COLLAB | B65: Heidelberg Medizin - Collaborative Seed Grant | C65: INSTITUTION | D65: ACADEMIA | E65: DE-BW | F65: UNI_HEIDELBERG_MED | G65: BASIC;CLINICAL;TRANSLATION | H65: ANY | I65: DISCOVERY;PRECLINICAL | J65: TRANSLATION;CLINICAL | K65: INSTITUTION | L65: SRC-V22-HDSEED | M65: P2 | N65: ACTIVE | O65: Befristete fakultatsinterne Anschubfoerderung; keine universelle DZIF-Foerderung. | P65: PR-V22-INST-HEIDELBERG-COLLAB | Q65: =IFERROR(IF(VLOOKUP(L65,SOURCE_REGISTRY!$A$2:$E$246,5,FALSE)="","",VLOOKUP(L65,SOURCE_REGISTRY!$A$2:$E$246,5,FALSE)),"") -> https://www.medizinische-fakultaet-hd.uni-heidelberg.de/forschung/forschungsfoerderung/foerderprogramme-der-fakultaet/collaborative-seed-grant-funding/ | S65: ALL | T65: CONDITIONAL
A66: REG_HE_LOEWE | B66: Hessen LOEWE - Forschung und Transfer | C66: PROGRAMME | D66: ACADEMIA;SME;CONSORTIUM;PUBLIC_BODY | E66: DE-HE | F66: ANY | G66: BASIC;TRANSLATION;BIOTECH | H66: ANY | I66: ANY | J66: TRANSLATION;CLINICAL | K66: REGION | L66: SRC-V22-LOEWE | M66: P2 | N66: ACTIVE | O66: Unterschiedliche LOEWE-Foerderlinien; akademisch, KMU-Verbund und Forschung nicht gleichsetzen. | P66: PR-V22-REG-HE-LOEWE | Q66: =IFERROR(IF(VLOOKUP(L66,SOURCE_REGISTRY!$A$2:$E$246,5,FALSE)="","",VLOOKUP(L66,SOURCE_REGISTRY!$A$2:$E$246,5,FALSE)),"") -> https://wissenschaft.hessen.de/forschen/forschungsfoerderprogramm-loewe | S66: ALL | T66: CONDITIONAL
